2024-09-02 00:10:28 align.main INFO : Reading netlist: /home/adair/Documents/CAD/magic_cds/extraction_custom/current_mirror_ota/current_mirror_ota.sp subckt=CURRENT_MIRROR_OTA, flat=0
2024-09-02 00:10:28 align.compiler.compiler INFO : Starting topology identification...
2024-09-02 00:10:30 align.compiler.user_const INFO : Reading constraint file: [PosixPath('/home/adair/Documents/CAD/magic_cds/extraction_custom/current_mirror_ota/current_mirror_ota.const.json')]
2024-09-02 00:10:30 align.cmdline ERROR : Fatal Error. Cannot proceed
Traceback (most recent call last):
  File "/home/adair/Documents/CAD/venv/lib/python3.10/site-packages/align/cmdline.py", line 197, in parse_args
    return schematic2layout(**vars(arguments))
  File "/home/adair/Documents/CAD/venv/lib/python3.10/site-packages/align/main.py", line 167, in schematic2layout
    primitive_lib = generate_hierarchy(netlist, subckt, topology_dir, flatten, pdk_dir)
  File "/home/adair/Documents/CAD/venv/lib/python3.10/site-packages/align/compiler/compiler.py", line 27, in generate_hierarchy
    ckt_data, primitive_library = compiler_input(
  File "/home/adair/Documents/CAD/venv/lib/python3.10/site-packages/align/compiler/compiler.py", line 83, in compiler_input
    create_data = CreateDatabase(ckt_parser, const_parse)
  File "/home/adair/Documents/CAD/venv/lib/python3.10/site-packages/align/compiler/create_database.py", line 26, in __init__
    self.add_user_const()
  File "/home/adair/Documents/CAD/venv/lib/python3.10/site-packages/align/compiler/create_database.py", line 59, in add_user_const
    self.const_parse.annotate_user_constraints(subckt)
  File "/home/adair/Documents/CAD/venv/lib/python3.10/site-packages/align/compiler/user_const.py", line 53, in annotate_user_constraints
    constraints = constraint.ConstraintDB.parse_file(json_path)
  File "pydantic/main.py", line 561, in pydantic.main.BaseModel.parse_file
  File "pydantic/parse.py", line 64, in pydantic.parse.load_file
  File "pydantic/parse.py", line 37, in pydantic.parse.load_str_bytes
  File "/usr/lib/python3.10/json/__init__.py", line 346, in loads
    return _default_decoder.decode(s)
  File "/usr/lib/python3.10/json/decoder.py", line 337, in decode
    obj, end = self.raw_decode(s, idx=_w(s, 0).end())
  File "/usr/lib/python3.10/json/decoder.py", line 353, in raw_decode
    obj, end = self.scan_once(s, idx)
json.decoder.JSONDecodeError: Expecting ',' delimiter: line 6 column 5 (char 303)
